<?xml version="1.0" encoding="utf-8" ?>
<!-- This URDF was automatically created by SolidWorks to URDF Exporter! Originally created by Stephen Brawner (brawner@gmail.com) 
     Commit Version: 1.6.0-4-g7f85cfe  Build Version: 1.6.7995.38578
     For more information, please see http://wiki.ros.org/sw_urdf_exporter -->
<robot name="oscar">
    <link name="Mesa">
        <inertial>
            <origin xyz="0 1.2490009027033E-16 -0.01" rpy="0 0 0" />
            <mass value="7.02" />
            <inertia ixx="0.356148" ixy="3.84706155820425E-17" ixz="8.44376651931703E-21" iyy="0.1186965" iyz="3.52365706057789E-19" izz="0.4743765" />
        </inertial>
        <visual>
            <origin xyz="0 0 0" rpy="0 0 0" />
            <geometry>
                <mesh filename="package://oscar/meshes/Mesa.STL" />
            </geometry>
            <material name="">
                <color rgba="0.792156862745098 0.819607843137255 0.933333333333333 1" />
            </material>
        </visual>
        <collision>
            <origin xyz="0 0 0" rpy="0 0 0" />
            <geometry>
                <mesh filename="package://oscar/meshes/Mesa.STL" />
            </geometry>
        </collision>
    </link>
    <link name="Thor1_BaseLink">
        <inertial>
            <origin xyz="-0.088732731563341 -0.000696290560320056 0.0403221329276099" rpy="0 0 0" />
            <mass value="1.35349565438478" />
            <inertia ixx="0.00345373135756371" ixy="2.21025986127605E-05" ixz="-2.39920619028571E-06" iyy="0.00657106226355986" iyz="1.04292423904486E-05" izz="0.00946412790798534" />
        </inertial>
        <visual>
            <origin xyz="0 0 0" rpy="0 0 0" />
            <geometry>
                <mesh filename="package://oscar/meshes/Thor1_BaseLink.STL" />
            </geometry>
            <material name="">
                <color rgba="0.792156862745098 0.819607843137255 0.933333333333333 1" />
            </material>
        </visual>
        <collision>
            <origin xyz="0 0 0" rpy="0 0 0" />
            <geometry>
                <mesh filename="package://oscar/meshes/Thor1_BaseLink.STL" />
            </geometry>
        </collision>
    </link>
    <joint name="MesaThor1" type="fixed">
        <origin xyz="0.115 -0.25 0" rpy="0 0 0" />
        <parent link="Mesa" />
        <child link="Thor1_BaseLink" />
        <axis xyz="0 0 0" />
    </joint>
    <link name="Thor1_Link1">
        <inertial>
            <origin xyz="-8.13322279868967E-06 0.00220511166887832 0.0721235751007446" rpy="0 0 0" />
            <mass value="0.528448201111755" />
            <inertia ixx="0.00147868606346454" ixy="1.84225927398496E-07" ixz="-1.88043504000894E-07" iyy="0.0016458071236998" iyz="-1.09432435994869E-05" izz="0.00141885836528446" />
        </inertial>
        <visual>
            <origin xyz="0 0 0" rpy="0 0 0" />
            <geometry>
                <mesh filename="package://oscar/meshes/Thor1_Link1.STL" />
            </geometry>
            <material name="">
                <color rgba="0.792156862745098 0.819607843137255 0.933333333333333 1" />
            </material>
        </visual>
        <collision>
            <origin xyz="0 0 0" rpy="0 0 0" />
            <geometry>
                <mesh filename="package://oscar/meshes/Thor1_Link1.STL" />
            </geometry>
        </collision>
    </link>
    <joint name="Thor1_Joint1" type="revolute">
        <origin xyz="0 0 0.0855" rpy="0 0 0" />
        <parent link="Thor1_BaseLink" />
        <child link="Thor1_Link1" />
        <axis xyz="0 0 1" />
        <limit lower="-3.14" upper="3.14" effort="0" velocity="0" />
    </joint>
    <link name="Thor1_Link2">
        <inertial>
            <origin xyz="1.68503473396697E-07 -0.00602416533059452 0.0873970017818179" rpy="0 0 0" />
            <mass value="0.748707024643049" />
            <inertia ixx="0.00126091714079404" ixy="2.11945398986836E-09" ixz="2.06522477556638E-07" iyy="0.00207599229058418" iyz="4.62627793506807E-06" izz="0.000967970733868419" />
        </inertial>
        <visual>
            <origin xyz="0 0 0" rpy="0 0 0" />
            <geometry>
                <mesh filename="package://oscar/meshes/Thor1_Link2.STL" />
            </geometry>
            <material name="">
                <color rgba="0.792156862745098 0.819607843137255 0.933333333333333 1" />
            </material>
        </visual>
        <collision>
            <origin xyz="0 0 0" rpy="0 0 0" />
            <geometry>
                <mesh filename="package://oscar/meshes/Thor1_Link2.STL" />
            </geometry>
        </collision>
    </link>
    <joint name="Thor1_Joint2" type="revolute">
        <origin xyz="0 0 0.116" rpy="0 0 0" />
        <parent link="Thor1_Link1" />
        <child link="Thor1_Link2" />
        <axis xyz="0 1 0" />
        <limit lower="-1.57" upper="1.57" effort="0" velocity="0" />
    </joint>
    <link name="Thor1_Link3">
        <inertial>
            <origin xyz="-0.000876620961288266 0.00735310117782434 0.012212233378787" rpy="0 0 0" />
            <mass value="0.337466726955714" />
            <inertia ixx="0.000878122776612644" ixy="3.94023197228323E-08" ixz="3.87921033565621E-06" iyy="0.000960914147898031" iyz="1.4374998999796E-06" izz="0.000512084757924641" />
        </inertial>
        <visual>
            <origin xyz="0 0 0" rpy="0 0 0" />
            <geometry>
                <mesh filename="package://oscar/meshes/Thor1_Link3.STL" />
            </geometry>
            <material name="">
                <color rgba="0.792156862745098 0.819607843137255 0.933333333333333 1" />
            </material>
        </visual>
        <collision>
            <origin xyz="0 0 0" rpy="0 0 0" />
            <geometry>
                <mesh filename="package://oscar/meshes/Thor1_Link3.STL" />
            </geometry>
        </collision>
    </link>
    <joint name="Thor1_Joint3" type="revolute">
        <origin xyz="0 0 0.16" rpy="0 0 0" />
        <parent link="Thor1_Link2" />
        <child link="Thor1_Link3" />
        <axis xyz="0 1 0" />
        <limit lower="-1.57" upper="1.57" effort="0" velocity="0" />
    </joint>
    <link name="Thor1_Link4">
        <inertial>
            <origin xyz="0.000125096015636372 -2.68102434501927E-05 0.119539752597568" rpy="0 0 0" />
            <mass value="0.443353136180227" />
            <inertia ixx="0.000818156815958452" ixy="-1.59438894670143E-07" ixz="-7.61447124293743E-09" iyy="0.000828622503870771" iyz="-2.12145230603761E-08" izz="0.000734466992584916" />
        </inertial>
        <visual>
            <origin xyz="0 0 0" rpy="0 0 0" />
            <geometry>
                <mesh filename="package://oscar/meshes/Thor1_Link4.STL" />
            </geometry>
            <material name="">
                <color rgba="0.792156862745098 0.819607843137255 0.933333333333333 1" />
            </material>
        </visual>
        <collision>
            <origin xyz="0 0 0" rpy="0 0 0" />
            <geometry>
                <mesh filename="package://oscar/meshes/Thor1_Link4.STL" />
            </geometry>
        </collision>
    </link>
    <joint name="Thor1_Joint4" type="revolute">
        <origin xyz="0 0 0.01" rpy="0 0 0" />
        <parent link="Thor1_Link3" />
        <child link="Thor1_Link4" />
        <axis xyz="0 0 1" />
        <limit lower="-3.14" upper="3.14" effort="0" velocity="0" />
    </joint>
    <link name="Thor1_Link5">
        <inertial>
            <origin xyz="1.96951839084303E-05 -8.60538408876677E-05 0.00125968021866163" rpy="0 0 0" />
            <mass value="0.0210713735594725" />
            <inertia ixx="3.34114385808647E-06" ixy="1.07782815564477E-21" ixz="-4.62195416042385E-18" iyy="3.16146785458146E-06" iyz="-5.19121045583867E-20" izz="2.94173670338704E-06" />
        </inertial>
        <visual>
            <origin xyz="0 0 0" rpy="0 0 0" />
            <geometry>
                <mesh filename="package://oscar/meshes/Thor1_Link5.STL" />
            </geometry>
            <material name="">
                <color rgba="0.792156862745098 0.819607843137255 0.933333333333333 1" />
            </material>
        </visual>
        <collision>
            <origin xyz="0 0 0" rpy="0 0 0" />
            <geometry>
                <mesh filename="package://oscar/meshes/Thor1_Link5.STL" />
            </geometry>
        </collision>
    </link>
    <joint name="Thor1_Joint5" type="revolute">
        <origin xyz="0 0 0.183" rpy="0 0 0" />
        <parent link="Thor1_Link4" />
        <child link="Thor1_Link5" />
        <axis xyz="0 1 0" />
        <limit lower="-1.57" upper="1.57" effort="0" velocity="0" />
    </joint>
    <link name="Thor1_Link6">
        <inertial>
            <origin xyz="-0.000115245777233097 4.26511816420394E-07 0.0189937181890166" rpy="0 0 0" />
            <mass value="0.0428804909649792" />
            <inertia ixx="1.84967966010554E-05" ixy="-8.49630537578657E-10" ixz="-4.75128756934783E-11" iyy="1.84958092478678E-05" iyz="9.05654752426967E-11" izz="1.86528444833182E-05" />
        </inertial>
        <visual>
            <origin xyz="0 0 0" rpy="0 0 0" />
            <geometry>
                <mesh filename="package://oscar/meshes/Thor1_Link6.STL" />
            </geometry>
            <material name="">
                <color rgba="0.792156862745098 0.819607843137255 0.933333333333333 1" />
            </material>
        </visual>
        <collision>
            <origin xyz="0 0 0" rpy="0 0 0" />
            <geometry>
                <mesh filename="package://oscar/meshes/Thor1_Link6.STL" />
            </geometry>
        </collision>
    </link>
    <joint name="Thor1_Joint6" type="revolute">
        <origin xyz="0.00011503 0 0.0099993" rpy="0 0 0" />
        <parent link="Thor1_Link5" />
        <child link="Thor1_Link6" />
        <axis xyz="0 0 1" />
        <limit lower="-3.14" upper="3.14" effort="0" velocity="0" />
    </joint>
    <link name="Thor1_Gripper">
        <inertial>
            <origin xyz="-0.00833013467649024 -0.000303355897597668 -0.0562584449883399" rpy="0 0 0" />
            <mass value="0.117341098785976" />
            <inertia ixx="4.11548965588065E-05" ixy="4.1855817604596E-08" ixz="9.21090231552191E-07" iyy="2.47325809445551E-05" iyz="-3.49966955337043E-07" izz="2.66067052306754E-05" />
        </inertial>
        <visual>
            <origin xyz="0 0 0" rpy="0 0 0" />
            <geometry>
                <mesh filename="package://oscar/meshes/Thor1_Gripper.STL" />
            </geometry>
            <material name="">
                <color rgba="0.792156862745098 0.819607843137255 0.933333333333333 1" />
            </material>
        </visual>
        <collision>
            <origin xyz="0 0 0" rpy="0 0 0" />
            <geometry>
                <mesh filename="package://oscar/meshes/Thor1_Gripper.STL" />
            </geometry>
        </collision>
    </link>
    <joint name="Thor1_efector" type="fixed">
        <origin xyz="-0.00026503 -0.00051111 0.1422" rpy="0 0 0" />
        <parent link="Thor1_Link6" />
        <child link="Thor1_Gripper" />
        <axis xyz="0 0 0" />
    </joint>
    <link name="Thor2_BaseLink">
        <inertial>
            <origin xyz="-0.0887327413871597 -0.000696288545400381 0.0403221343206042" rpy="0 0 0" />
            <mass value="1.35349575334164" />
            <inertia ixx="0.00345373142810176" ixy="2.21026518075428E-05" ixz="-2.39919990351711E-06" iyy="0.00657106233625328" iyz="1.04292369753038E-05" izz="0.00946412805045056" />
        </inertial>
        <visual>
            <origin xyz="0 0 0" rpy="0 0 0" />
            <geometry>
                <mesh filename="package://oscar/meshes/Thor2_BaseLink.STL" />
            </geometry>
            <material name="">
                <color rgba="0.792156862745098 0.819607843137255 0.933333333333333 1" />
            </material>
        </visual>
        <collision>
            <origin xyz="0 0 0" rpy="0 0 0" />
            <geometry>
                <mesh filename="package://oscar/meshes/Thor2_BaseLink.STL" />
            </geometry>
        </collision>
    </link>
    <joint name="MesaThor2" type="fixed">
        <origin xyz="0.115 0.25 0" rpy="0 0 0" />
        <parent link="Mesa" />
        <child link="Thor2_BaseLink" />
        <axis xyz="0 0 0" />
    </joint>
    <link name="Thor2_Link1">
        <inertial>
            <origin xyz="-8.1332227889197E-06 0.00220511166888307 0.0721235751007427" rpy="0 0 0" />
            <mass value="0.528448201111754" />
            <inertia ixx="0.00147868606346454" ixy="1.84225927394288E-07" ixz="-1.88043504001821E-07" iyy="0.0016458071236998" iyz="-1.09432435994845E-05" izz="0.00141885836528446" />
        </inertial>
        <visual>
            <origin xyz="0 0 0" rpy="0 0 0" />
            <geometry>
                <mesh filename="package://oscar/meshes/Thor2_Link1.STL" />
            </geometry>
            <material name="">
                <color rgba="0.792156862745098 0.819607843137255 0.933333333333333 1" />
            </material>
        </visual>
        <collision>
            <origin xyz="0 0 0" rpy="0 0 0" />
            <geometry>
                <mesh filename="package://oscar/meshes/Thor2_Link1.STL" />
            </geometry>
        </collision>
    </link>
    <joint name="Thor2_Joint1" type="revolute">
        <origin xyz="0 0 0.0855" rpy="0 0 0" />
        <parent link="Thor2_BaseLink" />
        <child link="Thor2_Link1" />
        <axis xyz="0 0 1" />
        <limit lower="-3.14" upper="3.14" effort="0" velocity="0" />
    </joint>
    <link name="Thor2_Link2">
        <inertial>
            <origin xyz="1.68503813124943E-07 -0.00602416533060843 0.0873970017817492" rpy="0 0 0" />
            <mass value="0.74870702464305" />
            <inertia ixx="0.00126091714079404" ixy="2.11945401700483E-09" ixz="2.06522476459294E-07" iyy="0.00207599229058419" iyz="4.62627793506703E-06" izz="0.000967970733868419" />
        </inertial>
        <visual>
            <origin xyz="0 0 0" rpy="0 0 0" />
            <geometry>
                <mesh filename="package://oscar/meshes/Thor2_Link2.STL" />
            </geometry>
            <material name="">
                <color rgba="0.792156862745098 0.819607843137255 0.933333333333333 1" />
            </material>
        </visual>
        <collision>
            <origin xyz="0 0 0" rpy="0 0 0" />
            <geometry>
                <mesh filename="package://oscar/meshes/Thor2_Link2.STL" />
            </geometry>
        </collision>
    </link>
    <joint name="Thor2_Joint2" type="revolute">
        <origin xyz="0 0 0.116" rpy="0 0 0" />
        <parent link="Thor2_Link1" />
        <child link="Thor2_Link2" />
        <axis xyz="0 1 0" />
        <limit lower="-1.57" upper="1.57" effort="0" velocity="0" />
    </joint>
    <link name="Thor2_Link3">
        <inertial>
            <origin xyz="-0.000876620961125951 0.00735310117782512 0.012212233378867" rpy="0 0 0" />
            <mass value="0.337466726955713" />
            <inertia ixx="0.000878122776612641" ixy="3.94023197230028E-08" ixz="3.87921033566083E-06" iyy="0.000960914147898029" iyz="1.43749989997835E-06" izz="0.000512084757924642" />
        </inertial>
        <visual>
            <origin xyz="0 0 0" rpy="0 0 0" />
            <geometry>
                <mesh filename="package://oscar/meshes/Thor2_Link3.STL" />
            </geometry>
            <material name="">
                <color rgba="0.792156862745098 0.819607843137255 0.933333333333333 1" />
            </material>
        </visual>
        <collision>
            <origin xyz="0 0 0" rpy="0 0 0" />
            <geometry>
                <mesh filename="package://oscar/meshes/Thor2_Link3.STL" />
            </geometry>
        </collision>
    </link>
    <joint name="Thor2_Joint3" type="revolute">
        <origin xyz="0 0 0.16" rpy="0 0 0" />
        <parent link="Thor2_Link2" />
        <child link="Thor2_Link3" />
        <axis xyz="0 1 0" />
        <limit lower="-1.57" upper="1.57" effort="0" velocity="0" />
    </joint>
    <link name="Thor2_Link4">
        <inertial>
            <origin xyz="0.00012509616454992 -2.68102434554662E-05 0.11704225259763" rpy="0 0 0" />
            <mass value="0.443353136180448" />
            <inertia ixx="0.000818156815958519" ixy="-1.59438894662387E-07" ixz="-7.61447126272308E-09" iyy="0.000828622503870833" iyz="-2.12145230401108E-08" izz="0.000734466992584937" />
        </inertial>
        <visual>
            <origin xyz="0 0 0" rpy="0 0 0" />
            <geometry>
                <mesh filename="package://oscar/meshes/Thor2_Link4.STL" />
            </geometry>
            <material name="">
                <color rgba="0.792156862745098 0.819607843137255 0.933333333333333 1" />
            </material>
        </visual>
        <collision>
            <origin xyz="0 0 0" rpy="0 0 0" />
            <geometry>
                <mesh filename="package://oscar/meshes/Thor2_Link4.STL" />
            </geometry>
        </collision>
    </link>
    <joint name="Thor2_Joint4" type="revolute">
        <origin xyz="0 0 0.012498" rpy="0 0 0" />
        <parent link="Thor2_Link3" />
        <child link="Thor2_Link4" />
        <axis xyz="0 0 1" />
        <limit lower="-3.14" upper="3.14" effort="0" velocity="0" />
    </joint>
    <link name="Thor2_Link5">
        <inertial>
            <origin xyz="1.96951841238135E-05 -8.60538408610778E-05 0.00125968021865008" rpy="0 0 0" />
            <mass value="0.0210713735594725" />
            <inertia ixx="3.34114385808646E-06" ixy="1.53247214399847E-21" ixz="-4.61488946045489E-18" iyy="3.16146785458145E-06" iyz="-5.36132829938127E-20" izz="2.94173670338703E-06" />
        </inertial>
        <visual>
            <origin xyz="0 0 0" rpy="0 0 0" />
            <geometry>
                <mesh filename="package://oscar/meshes/Thor2_Link5.STL" />
            </geometry>
            <material name="">
                <color rgba="0.792156862745098 0.819607843137255 0.933333333333333 1" />
            </material>
        </visual>
        <collision>
            <origin xyz="0 0 0" rpy="0 0 0" />
            <geometry>
                <mesh filename="package://oscar/meshes/Thor2_Link5.STL" />
            </geometry>
        </collision>
    </link>
    <joint name="Thor2_Joint5" type="revolute">
        <origin xyz="0 0 0.1805" rpy="0 0 0" />
        <parent link="Thor2_Link4" />
        <child link="Thor2_Link5" />
        <axis xyz="0 1 0" />
        <limit lower="-1.57" upper="1.57" effort="0" velocity="0" />
    </joint>
    <link name="Thor2_Link6">
        <inertial>
            <origin xyz="-0.000115245776520889 4.26511943873997E-07 0.0189937181891761" rpy="0 0 0" />
            <mass value="0.0428804909638117" />
            <inertia ixx="1.84967966006921E-05" ixy="-8.49630545949047E-10" ixz="-4.75127098962645E-11" iyy="1.84958092470652E-05" iyz="9.05654992005295E-11" izz="1.86528444822865E-05" />
        </inertial>
        <visual>
            <origin xyz="0 0 0" rpy="0 0 0" />
            <geometry>
                <mesh filename="package://oscar/meshes/Thor2_Link6.STL" />
            </geometry>
            <material name="">
                <color rgba="0.792156862745098 0.819607843137255 0.933333333333333 1" />
            </material>
        </visual>
        <collision>
            <origin xyz="0 0 0" rpy="0 0 0" />
            <geometry>
                <mesh filename="package://oscar/meshes/Thor2_Link6.STL" />
            </geometry>
        </collision>
    </link>
    <joint name="Thor2_Joint6" type="revolute">
        <origin xyz="0.00011503 0 0.0099993" rpy="0 0 0" />
        <parent link="Thor2_Link5" />
        <child link="Thor2_Link6" />
        <axis xyz="0 0 1" />
        <limit lower="-3.14" upper="3.14" effort="0" velocity="0" />
    </joint>
    <link name="Thor2_Gripper">
        <inertial>
            <origin xyz="-0.00833274182551802 -0.000303340874809682 -0.0562549543683204" rpy="0 0 0" />
            <mass value="0.117341098402648" />
            <inertia ixx="4.11548964078966E-05" ixy="4.18557140605978E-08" ixz="9.21090209153993E-07" iyy="2.47325809159059E-05" iyz="-3.49966906400361E-07" izz="2.66067050012778E-05" />
        </inertial>
        <visual>
            <origin xyz="0 0 0" rpy="0 0 0" />
            <geometry>
                <mesh filename="package://oscar/meshes/Thor2_Gripper.STL" />
            </geometry>
            <material name="">
                <color rgba="0.792156862745098 0.819607843137255 0.933333333333333 1" />
            </material>
        </visual>
        <collision>
            <origin xyz="0 0 0" rpy="0 0 0" />
            <geometry>
                <mesh filename="package://oscar/meshes/Thor2_Gripper.STL" />
            </geometry>
        </collision>
    </link>
    <joint name="Thor2_efector" type="fixed">
        <origin xyz="-0.00026243 -0.00051112 0.1422" rpy="0 0 0" />
        <parent link="Thor2_Link6" />
        <child link="Thor2_Gripper" />
        <axis xyz="0 0 0" />
    </joint>
    <link name="SoporteCamara">
        <inertial>
            <origin xyz="0.089524931063286 -0.000280264063290292 0.495224569426337" rpy="0 0 0" />
            <mass value="1.17060628045216" />
            <inertia ixx="0.0241579833272484" ixy="-8.67518141012337E-17" ixz="-0.000137279815063728" iyy="0.0324638841805806" iyz="-1.4456267102742E-18" izz="0.00867798265212148" />
        </inertial>
        <visual>
            <origin xyz="0 0 0" rpy="0 0 0" />
            <geometry>
                <mesh filename="package://oscar/meshes/SoporteCamara.STL" />
            </geometry>
            <material name="">
                <color rgba="0.792156862745098 0.819607843137255 0.933333333333333 1" />
            </material>
        </visual>
        <collision>
            <origin xyz="0 0 0" rpy="0 0 0" />
            <geometry>
                <mesh filename="package://oscar/meshes/SoporteCamara.STL" />
            </geometry>
        </collision>
    </link>
    <joint name="MesaSoporte" type="fixed">
        <origin xyz="0.0494 0 0" rpy="0 0 0" />
        <parent link="Mesa" />
        <child link="SoporteCamara" />
        <axis xyz="0 0 0" />
    </joint>
    <transmission name="trans_Thor1_Joint1">
        <type>transmission_interface/SimpleTransmission</type>
        <joint name="Thor1_Joint1">
            <hardwareInterface>hardware_interface/PositionJointInterface</hardwareInterface>
        </joint>
        <actuator name="Thor1_Joint1_motor">
            <hardwareInterface>hardware_interface/PositionJointInterface</hardwareInterface>
            <mechanicalReduction>1</mechanicalReduction>
        </actuator>
    </transmission>
    <transmission name="trans_Thor1_Joint2">
        <type>transmission_interface/SimpleTransmission</type>
        <joint name="Thor1_Joint2">
            <hardwareInterface>hardware_interface/PositionJointInterface</hardwareInterface>
        </joint>
        <actuator name="Thor1_Joint2_motor">
            <hardwareInterface>hardware_interface/PositionJointInterface</hardwareInterface>
            <mechanicalReduction>1</mechanicalReduction>
        </actuator>
    </transmission>
    <transmission name="trans_Thor1_Joint3">
        <type>transmission_interface/SimpleTransmission</type>
        <joint name="Thor1_Joint3">
            <hardwareInterface>hardware_interface/PositionJointInterface</hardwareInterface>
        </joint>
        <actuator name="Thor1_Joint3_motor">
            <hardwareInterface>hardware_interface/PositionJointInterface</hardwareInterface>
            <mechanicalReduction>1</mechanicalReduction>
        </actuator>
    </transmission>
    <transmission name="trans_Thor1_Joint4">
        <type>transmission_interface/SimpleTransmission</type>
        <joint name="Thor1_Joint4">
            <hardwareInterface>hardware_interface/PositionJointInterface</hardwareInterface>
        </joint>
        <actuator name="Thor1_Joint4_motor">
            <hardwareInterface>hardware_interface/PositionJointInterface</hardwareInterface>
            <mechanicalReduction>1</mechanicalReduction>
        </actuator>
    </transmission>
    <transmission name="trans_Thor1_Joint5">
        <type>transmission_interface/SimpleTransmission</type>
        <joint name="Thor1_Joint5">
            <hardwareInterface>hardware_interface/PositionJointInterface</hardwareInterface>
        </joint>
        <actuator name="Thor1_Joint5_motor">
            <hardwareInterface>hardware_interface/PositionJointInterface</hardwareInterface>
            <mechanicalReduction>1</mechanicalReduction>
        </actuator>
    </transmission>
    <transmission name="trans_Thor1_Joint6">
        <type>transmission_interface/SimpleTransmission</type>
        <joint name="Thor1_Joint6">
            <hardwareInterface>hardware_interface/PositionJointInterface</hardwareInterface>
        </joint>
        <actuator name="Thor1_Joint6_motor">
            <hardwareInterface>hardware_interface/PositionJointInterface</hardwareInterface>
            <mechanicalReduction>1</mechanicalReduction>
        </actuator>
    </transmission>
    <transmission name="trans_Thor2_Joint1">
        <type>transmission_interface/SimpleTransmission</type>
        <joint name="Thor2_Joint1">
            <hardwareInterface>hardware_interface/PositionJointInterface</hardwareInterface>
        </joint>
        <actuator name="Thor2_Joint1_motor">
            <hardwareInterface>hardware_interface/PositionJointInterface</hardwareInterface>
            <mechanicalReduction>1</mechanicalReduction>
        </actuator>
    </transmission>
    <transmission name="trans_Thor2_Joint2">
        <type>transmission_interface/SimpleTransmission</type>
        <joint name="Thor2_Joint2">
            <hardwareInterface>hardware_interface/PositionJointInterface</hardwareInterface>
        </joint>
        <actuator name="Thor2_Joint2_motor">
            <hardwareInterface>hardware_interface/PositionJointInterface</hardwareInterface>
            <mechanicalReduction>1</mechanicalReduction>
        </actuator>
    </transmission>
    <transmission name="trans_Thor2_Joint3">
        <type>transmission_interface/SimpleTransmission</type>
        <joint name="Thor2_Joint3">
            <hardwareInterface>hardware_interface/PositionJointInterface</hardwareInterface>
        </joint>
        <actuator name="Thor2_Joint3_motor">
            <hardwareInterface>hardware_interface/PositionJointInterface</hardwareInterface>
            <mechanicalReduction>1</mechanicalReduction>
        </actuator>
    </transmission>
    <transmission name="trans_Thor2_Joint4">
        <type>transmission_interface/SimpleTransmission</type>
        <joint name="Thor2_Joint4">
            <hardwareInterface>hardware_interface/PositionJointInterface</hardwareInterface>
        </joint>
        <actuator name="Thor2_Joint4_motor">
            <hardwareInterface>hardware_interface/PositionJointInterface</hardwareInterface>
            <mechanicalReduction>1</mechanicalReduction>
        </actuator>
    </transmission>
    <transmission name="trans_Thor2_Joint5">
        <type>transmission_interface/SimpleTransmission</type>
        <joint name="Thor2_Joint5">
            <hardwareInterface>hardware_interface/PositionJointInterface</hardwareInterface>
        </joint>
        <actuator name="Thor2_Joint5_motor">
            <hardwareInterface>hardware_interface/PositionJointInterface</hardwareInterface>
            <mechanicalReduction>1</mechanicalReduction>
        </actuator>
    </transmission>
    <transmission name="trans_Thor2_Joint6">
        <type>transmission_interface/SimpleTransmission</type>
        <joint name="Thor2_Joint6">
            <hardwareInterface>hardware_interface/PositionJointInterface</hardwareInterface>
        </joint>
        <actuator name="Thor2_Joint6_motor">
            <hardwareInterface>hardware_interface/PositionJointInterface</hardwareInterface>
            <mechanicalReduction>1</mechanicalReduction>
        </actuator>
    </transmission>
    <gazebo>
        <plugin name="gazebo_ros_control">
            <robotNamespace>/</robotNamespace>
        </plugin>
    </gazebo>
</robot>

